Workbook

Sheet FloodArchive
A1: ID | B1: GlideNumber | C1: Country | D1: OtherCountry | E1: long | F1: lat | G1: Area | H1: Began | I1: Ended | J1: Validation | K1: Dead | L1: Displaced | M1: MainCause | N1: Severity
A2: 1591 | B2: 0 | C2: Argentina | D2: 0 | E2: -64.9075 | F2: -27.1696 | G2: 782982.74 | H2: 36594 | I2: 36602 | J2: News | K2: 7 | L2: 15000 | M2: Heavy rain | N2: 1
A3: 1618 | B3: 0 | C3: Brazil | D3: 0 | E3: -36.2564 | F3: -9.17889 | G3: 47599.03 | H3: 36737 | I3: 36755 | J3: News | K3: 70 | L3: 120000 | M3: Brief torrential rain | N3: 1
A4: 1596 | B4: 0 | C4: China | D4: 0 | E4: 113.381 | F4: 22.5981 | G4: 21168.02 | H4: 36629 | I4: 36633 | J4: News | K4: 15 | L4: 0 | M4: Heavy rain | N4: 1
A5: 1624 | B5: 0 | C5: Ethiopia | D5: 0 | E5: 40.6091 | F5: 10.5157 | G5: 57517.62 | H5: 36748 | I5: 36759 | J5: News | K5: 9 | L5: 30000 | M5: Heavy rain | N5: 1
A6: 1484 | B6: 0 | C6: Fiji | E6: 179.037 | F6: -18.0546 | G6: 6286.31 | H6: 36167 | I6: 36170 | J6: News | K6: 0 | L6: 0 | M6: 0 | N6: 1
A7: 180 | B7: 0 | C7: India | E7: 92.0622 | F7: 26.4813 | G7: 42285.99 | H7: 32286 | I7: 32305 | J7: News | K7: 76 | L7: 43000 | M7: Monsoonal rain | N7: 1
A8: 1641 | B8: 0 | C8: India | D8: 0 | E8: 88.5453 | F8: 24.0841 | G8: 155000.88 | H8: 36787 | I8: 36820 | J8: News | K8: 1468 | L8: 24000000 | M8: Monsoonal rain | N8: 2
A9: 1615 | B9: 0 | C9: India | D9: 0 | E9: 74.5207 | F9: 15.811 | G9: 107052.9 | H9: 36724 | I9: 36737 | J9: News | K9: 140 | L9: 0 | M9: Monsoonal rain | N9: 1
A10: 2081 | B10: 0 | C10: India | D10: 0 | E10: 79.0643 | F10: 10.9485 | G10: 22713.01 | H10: 37560 | I10: 37564 | J10: News | K10: 20 | L10: 300 | M10: Heavy rain | N10: 1
A11: 1606 | B11: 0 | C11: India | D11: 0 | E11: 94.7981 | F11: 27.4268 | G11: 55286.73 | H11: 36687 | I11: 36693 | J11: News | K11: 30 | L11: 50000 | M11: Dam/Levy, break or release | N11: 2
A12: 1616 | B12: 0 | C12: India | D12: 0 | E12: 77.6925 | F12: 31.806 | G12: 12415.81 | H12: 36738 | I12: 36742 | J12: News | K12: 140 | L12: 4000 | M12: Brief torrential rain | N12: 1
A13: 1623 | B13: 0 | C13: India | D13: 0 | E13: 79.2098 | F13: 17.1335 | G13: 129459.76 | H13: 36761 | I13: 36769 | J13: News | K13: 162 | L13: 3000000 | M13: Brief torrential rain | N13: 2
A14: 1626 | B14: 0 | C14: India | D14: 0 | E14: 80.4678 | F14: 26.9607 | G14: 223178.01 | H14: 36767 | I14: 36783 | J14: News | K14: 578 | L14: 0 | M14: Monsoonal rain | N14: 1
A15: 1737 | B15: 0 | C15: India | D15: 0 | E15: 71.2868 | F15: 22.8284 | G15: 38728.34 | H15: 37062 | I15: 37063 | J15: News | K15: 29 | L15: 0 | M15: Monsoonal rain | N15: 1
A16: 2002 | B16: 0 | C16: Iran | D16: 0 | E16: 48.0673 | F16: 37.6146 | G16: 993.753 | H16: 37460 | I16: 37463 | J16: News | K16: 6 | L16: 0 | M16: Heavy rain | N16: 1
A17: 2099 | B17: 0 | C17: Italy | D17: 0 | E17: 8.64237 | F17: 45.8293 | G17: 29901.95 | H17: 37582 | I17: 37593 | J17: News | K17: 0 | L17: 10000 | M17: Heavy rain | N17: 1
A18: 1640 | B18: 0 | C18: Mexico | D18: 0 | E18: -100.301 | F18: 17.2579 | G18: 12755.85 | H18: 36788 | I18: 36791 | J18: News | K18: 9 | L18: 0 | M18: Heavy rain | N18: 1
A19: 1739 | B19: 0 | C19: Nepal | D19: 0 | E19: 84.82 | F19: 27.8773 | G19: 469.056 | H19: 37068 | I19: 37068 | J19: News | K19: 35 | L19: 0 | M19: Heavy rain | N19: 1
... A69: 2727 | B69: 0 | C69: Afghanistan | D69: 0 | E69: 71.0849 | F69: 34.9305 | G69: 3208.66 | H69: 38606 | I69: 38607 | J69: News | K69: 12 | L69: 0 | M69: Heavy rain | N69: 1
A70: 2855 | B70: FL-2006-000076-AFG | C70: Afghanistan | D70: 0 | E70: 66.833 | F70: 35.6716 | G70: 58309.39 | H70: 38836 | I70: 38838 | J70: News | K70: 9 | L70: 400 | M70: Brief torrential rain | N70: 1
A71: 2866 | B71: 0 | C71: Afghanistan | D71: 0 | E71: 65.5588 | F71: 34.5163 | G71: 21480.76 | H71: 38856 | I71: 38860 | J71: News | K71: 9 | L71: 800 | M71: Heavy rain | N71: 1
A72: 2907 | B72: 0 | C72: Afghanistan | D72: 0 | E72: 69.1265 | F72: 35.9525 | G72: 1570.85 | H72: 38901 | I72: 38902 | J72: News | K72: 7 | L72: 0 | M72: Heavy rain | N72: 1
A73: 2936 | B73: FL-2006-000128-AFG | C73: Afghanistan | D73: 0 | E73: 69.7467 | F73: 34.0789 | G73: 63167.25 | H73: 38928 | I73: 38938 | J73: News | K73: 35 | L73: 0 | M73: Heavy rain | N73: 1
A74: 2992 | B74: FF-2006-000163-AFG | C74: Afghanistan | D74: 0 | E74: 70.7909 | F74: 34.2199 | G74: 1385.12 | H74: 39031 | I74: 39033 | J74: News | K74: 9 | L74: 0 | M74: Heavy rain | N74: 1
A75: 2994 | B75: FF-2006-000168-AFG | C75: Afghanistan | D75: 0 | E75: 63.544 | F75: 35.6213 | G75: 4953.7 | H75: 39037 | I75: 39041 | J75: News | K75: 66 | L75: 4500 | M75: Heavy rain | N75: 1
A76: 2995 | B76: 0 | C76: Afghanistan | D76: 0 | E76: 66.1253 | F76: 32.7423 | G76: 21502.28 | H76: 39040 | I76: 39042 | J76: News | K76: 50 | L76: 0 | M76: Heavy rain | N76: 1
A77: 2996 | B77: 0 | C77: Afghanistan | D77: 0 | E77: 63.8569 | F77: 33.1462 | G77: 565.035 | H77: 39040 | I77: 39042 | J77: News | K77: 18 | L77: 0 | M77: Heavy rain | N77: 1
A78: 3040 | B78: FL-2007-000045-AFG | C78: Afghanistan | D78: 0 | E78: 64.8947 | F78: 33.2456 | G78: 656435.88 | H78: 39159 | I78: 39177 | J78: News | K78: 104 | L78: 20000 | M78: Heavy rain | N78: 1
A79: 3055 | B79: 0 | C79: Afghanistan | D79: 0 | E79: 69.6682 | F79: 35.2702 | G79: 40765.63 | H79: 39189 | I79: 39190 | J79: News | K79: 6 | L79: 0 | M79: Heavy rain | N79: 1
A80: 3061 | B80: 0 | C80: Afghanistan | D80: 0 | E80: 70.7315 | F80: 37.0063 | G80: 27490.25 | H80: 39195 | I80: 39206 | J80: News | K80: 36 | L80: 0 | M80: Heavy rain | N80: 1
A81: 3069 | B81: FL-2007-000054-AFG | C81: Afghanistan | D81: 0 | E81: 68.8518 | F81: 36.2949 | G81: 25847.23 | H81: 39207 | I81: 39209 | J81: News | K81: 12 | L81: 0 | M81: Heavy rain | N81: 1
A82: 3077 | B82: 0 | C82: Afghanistan | D82: 0 | E82: 70.6001 | F82: 36.5247 | G82: 15491.94 | H82: 39216 | I82: 39220 | J82: News | K82: 34 | L82: 0 | M82: Heavy rain | N82: 1
A83: 3109 | B83: FF-2007-000091-AFG | C83: Afghanistan | D83: 0 | E83: 71.1407 | F83: 35.2782 | G83: 62335.91 | H83: 39257 | I83: 39266 | J83: News | K83: 113 | L83: 4000 | M83: Heavy rain | N83: 1
A84: 3130 | B84: 0 | C84: Afghanistan | D84: 0 | E84: 66.1314 | F84: 34.5303 | G84: 4112.52 | H84: 39278 | I84: 39280 | J84: News | K84: 9 | L84: 0 | M84: Heavy rain | N84: 1
A85: 3258 | B85: 0 | C85: Afghanistan | D85: 0 | E85: 64.2796 | F85: 31.345 | G85: 18278.94 | H85: 39460 | I85: 39467 | J85: News | K85: 5 | L85: 300 | M85: Heavy rain | N85: 1
A86: 3471 | B86: FL-2009-000080-AFG | C86: Afghanistan | D86: 0 | E86: 63.5929 | F86: 33.0736 | G86: 88516.93 | H86: 39904 | I86: 39912 | J86: News | K86: 0 | L86: 200 | M86: Ice jam/break-up | N86: 1
A87: 3479 | B87: 0 | C87: Afghanistan | D87: 0 | E87: 64.3991 | F87: 34.88 | G87: 58894.07 | H87: 39936 | I87: 39943 | J87: News | K87: 0 | L87: 0 | M87: Heavy Rain | N87: 2
A88: 3604 | B88: FL-2010-000021-AFG | C88: Afghanistan | D88: 0 | E88: 65.1089 | F88: 32.547 | G88: 105873.35 | H88: 40214 | I88: 40219 | J88: 0 | K88: 20 | L88: 200 | M88: Heavy Rain | N88: 2
A89: 3643 | B89: FL-2010-000086-AFG | C89: Afghanistan | D89: 0 | E89: 62.2514 | F89: 34.3839 | G89: 65810.91 | H89: 40302 | I89: 40312 | J89: 0 | K89: 70 | L89: 40000 | M89: Torrential Rain | N89: 1
...

Sheet Sheet1
A3: Flood year | B3: Count of ID | C3: Sum of Area
A4: 1985 | B4: 1 | C4: 74615.9
A5: 1988 | B5: 6 | C5: 147463.99
A6: 1990 | B6: 3 | C6: 45061.73
A7: 1991 | B7: 1 | C7: 22908.02
A8: 1992 | B8: 1 | C8: 42369.21
A9: 1994 | B9: 1 | C9: 317262.41
A10: 1995 | B10: 1 | C10: 19768.44
A11: 1997 | B11: 1 | C11: 17287.47
A12: 1998 | B12: 2 | C12: 68804.11
A13: 1999 | B13: 2 | C13: 1113252
A14: 2002 | B14: 1 | C14: 1657.33
A15: 2003 | B15: 9 | C15: 449965.88
... A32: 2001 | B32: 2 | C32: 15352.34
A33: Grand Total | B33: 68 | C33: 6541185.3

Sheet Flood_Data
A1: ID | B1: GlideNumber | C1: Country | D1: OtherCountry | E1: long | F1: lat | G1: Area | H1: Began | I1: Ended | J1: Validation | K1: Dead | L1: Displaced | M1: MainCause | N1: Severity | O1: Flood year
A2: 55 | B2: 0 | C2: Nigeria | D2: 0 | E2: 6.50345 | F2: 6.41486 | G2: 74615.9 | H2: 31313 | I2: 31315 | J2: News | K2: 0 | L2: 6000 | M2: Heavy Rain | N2: 1 | O2: =YEAR(H2) -> 1985
A3: 249 | B3: 0 | C3: Nigeria | E3: 2.40705 | F3: 9.50559 | G3: 71964.13 | H3: 32400 | I3: 32412 | J3: News | K3: 7 | L3: 136000 | M3: Torrential rain | N3: 1 | O3: =YEAR(H3) -> 1988
A4: 257 | B4: 0 | C4: Nigeria | D4: 0 | E4: 7.10119 | F4: 6.37902 | G4: 8884.3 | H4: 32407 | I4: 32421 | J4: News | K4: 0 | L4: 70000 | M4: Dam/Levy, break or release | N4: 1 | O4: =YEAR(H4) -> 1988
A5: 430 | B5: 0 | C5: Nigeria | D5: 0 | E5: 3.51739 | F5: 6.53686 | G5: 3421.54 | H5: 33057 | I5: 33058 | J5: News | K5: 5 | L5: 3000 | M5: Heavy rain | N5: 1 | O5: =YEAR(H5) -> 1990
A6: 443 | B6: 0 | C6: Nigeria | D6: 0 | E6: 8.3879 | F6: 5.84049 | G6: 5516.12 | H6: 33087 | I6: 33088 | J6: News | K6: 100 | L6: 0 | M6: Heavy rain | N6: 1 | O6: =YEAR(H6) -> 1990
A7: 459 | B7: 0 | C7: Nigeria | D7: 0 | E7: 8.88898 | F7: 7.50054 | G7: 36124.07 | H7: 33132 | I7: 33137 | J7: News | K7: 0 | L7: 300000 | M7: Heavy rain | N7: 1 | O7: =YEAR(H7) -> 1990
A8: 559 | B8: 0 | C8: Nigeria | D8: 0 | E8: 8.52892 | F8: 11.69 | G8: 22908.02 | H8: 33454 | I8: 33455 | J8: News | K8: 4 | L8: 10000 | M8: Heavy rain | N8: 1 | O8: =YEAR(H8) -> 1991
A9: 698 | B9: 0 | C9: Nigeria | D9: 0 | E9: 13.018 | F9: 10.2805 | G9: 42369.21 | H9: 33869 | I9: 33870 | J9: News | K9: 9 | L9: 13000 | M9: Heavy rain | N9: 1 | O9: =YEAR(H9) -> 1992
A10: 899 | B10: 0 | C10: Nigeria | D10: Niger | E10: 13.3184 | F10: 12.0384 | G10: 317262.41 | H10: 34588 | I10: 34592 | J10: News | K10: 142 | L10: 180000 | M10: Heavy rain | N10: 1 | O10: =YEAR(H10) -> 1994
A11: 980 | B11: 0 | C11: Nigeria | D11: 0 | E11: 8.96747 | F11: 10.0459 | G11: 19768.44 | H11: 34918 | I11: 34921 | J11: News | K11: 30 | L11: 0 | M11: Heavy rain | N11: 1 | O11: =YEAR(H11) -> 1995
A12: 1219 | B12: 0 | C12: Nigeria | D12: 0 | E12: 4.03785 | F12: 7.46328 | G12: 17287.47 | H12: 35550 | I12: 35551 | J12: News | K12: 5 | L12: 0 | M12: Heavy rain | N12: 1 | O12: =YEAR(H12) -> 1997
A13: 1431 | B13: 0 | C13: Nigeria | D13: 0 | E13: 8.9692 | F13: 11.8968 | G13: 39717.53 | H13: 36022 | I13: 36023 | J13: News | K13: 15 | L13: 5000 | M13: Heavy rain | N13: 1 | O13: =YEAR(H13) -> 1998
A14: 1454 | B14: 0 | C14: Nigeria | D14: 0 | E14: 4.48983 | F14: 8.84162 | G14: 29086.58 | H14: 36080 | I14: 36086 | J14: News | K14: 0 | L14: 110000 | M14: Heavy rain | N14: 1 | O14: =YEAR(H14) -> 1998
A15: 1560 | B15: 0 | C15: Nigeria | D15: Ghana | E15: 5.9793 | F15: 12.5634 | G15: 861989.44 | H15: 36418 | I15: 36444 | J15: News | K15: 85 | L15: 396748 | M15: Heavy rain | N15: 2 | O15: =YEAR(H15) -> 1999
A16: 1563 | B16: 0 | C16: Nigeria | D16: 0 | E16: 11.938 | F16: 6.60512 | G16: 251262.56 | H16: 36459 | I16: 36472 | J16: News | K16: 50 | L16: 0 | M16: Heavy rain | N16: 2 | O16: =YEAR(H16) -> 1999
A17: 2003 | B17: 0 | C17: Nigeria | D17: 0 | E17: 3.28106 | F17: 6.60559 | G17: 1657.33 | H17: 37461 | I17: 37463 | J17: News | K17: 2 | L17: 0 | M17: Heavy rain | N17: 1 | O17: =YEAR(H17) -> 2002
A18: 2247 | B18: 0 | C18: Nigeria | D18: 0 | E18: 9.78959 | F18: 12.4276 | G18: 5709.91 | H18: 37779 | I18: 37780 | J18: News | K18: 0 | L18: 2000 | M18: Heavy rain | N18: 1 | O18: =YEAR(H18) -> 2003
A19: 2250 | B19: 0 | C19: Nigeria | D19: 0 | E19: 8.43421 | F19: 11.81 | G19: 785.174 | H19: 37769 | I19: 37770 | J19: News | K19: 1 | L19: 800 | M19: Brief torrential rain | N19: 1 | O19: =YEAR(H19) -> 2003
A20: 2290 | B20: 0 | C20: Nigeria | D20: 0 | E20: 8.94298 | F20: 6.28577 | G20: 8171.95 | H20: 37825 | I20: 37827 | J20: News | K20: 5 | L20: 0 | M20: Heavy rain | N20: 1 | O20: =YEAR(H20) -> 2003
A21: 2293 | B21: 0 | C21: Nigeria | D21: 0 | E21: 11.1736 | F21: 10.1997 | G21: 1524.21 | H21: 37824 | I21: 37826 | J21: News | K21: 0 | L21: 160 | M21: Heavy rain | N21: 1 | O21: =YEAR(H21) -> 2003
A22: 2294 | B22: 0 | C22: Nigeria | D22: 0 | E22: 9.13461 | F22: 6.92886 | G22: 2626.51 | H22: 37829 | I22: 37829 | J22: News | K22: 2 | L22: 3000 | M22: Heavy rain | N22: 1 | O22: =YEAR(H22) -> 2003
A23: 2311 | B23: 0 | C23: Nigeria | D23: 0 | E23: 4.73527 | F23: 12.3948 | G23: 138852.9 | H23: 37838 | I23: 37906 | J23: News | K23: 7 | L23: 10000 | M23: Heavy rain | N23: 1 | O23: =YEAR(H23) -> 2003
A24: 2314 | B24: 0 | C24: Nigeria | D24: 0 | E24: 10.0128 | F24: 12.6343 | G24: 19628.97 | H24: 37838 | I24: 37906 | J24: News | K24: 7 | L24: 10000 | M24: Heavy rain | N24: 1 | O24: =YEAR(H24) -> 2003
A25: 2345 | B25: 0 | C25: Nigeria | D25: 0 | E25: 7.48686 | F25: 10.5143 | G25: 134916.26 | H25: 37869 | I25: 37922 | J25: News | K25: 16 | L25: 210000 | M25: Heavy rain | N25: 1 | O25: =YEAR(H25) -> 2003
A26: 2361 | B26: 0 | C26: Nigeria | D26: 0 | E26: 11.9235 | F26: 8.87752 | G26: 137750 | H26: 37886 | I26: 37904 | J26: News | K26: 28 | L26: 1000 | M26: Heavy rain | N26: 1 | O26: =YEAR(H26) -> 2003
A27: 2503 | B27: 0 | C27: Nigeria | D27: 0 | E27: 3.48641 | F27: 6.4901 | G27: 337.173 | H27: 38155 | I27: 38156 | J27: News | K27: 0 | L27: 0 | M27: Heavy rain | N27: 1 | O27: =YEAR(H27) -> 2004
... A36: 2967 | B36: 0 | C36: Nigeria | D36: 0 | E36: 5.34617 | F36: 8.16231 | G36: 869.89 | H36: 38972 | I36: 38973 | J36: News | K36: 20 | L36: 0 | M36: Brief torrential rain | N36: 1 | O36: =YEAR(H36) -> 2006
A37: 3148 | B37: FL-2007-000123-NGA | C37: Nigeria | D37: 0 | E37: 3.29858 | F37: 6.958 | G37: 5268.18 | H37: 39295 | I37: 39309 | J37: News | K37: 6 | L37: 5000 | M37: Heavy rain | N37: 1 | O37: =YEAR(H37) -> 2007
A38: 3151 | B38: FL-2007-000123-NGA | C38: Nigeria | D38: 0 | E38: 11.7484 | F38: 10.2921 | G38: 630120.85 | H38: 39298 | I38: 39376 | J38: News | K38: 101 | L38: 140000 | M38: Heavy rain | N38: 1 | O38: =YEAR(H38) -> 2007
A39: 3540 | B39: 0 | C39: Nigeria | D39: 0 | E39: 5.68204 | F39: 12.2596 | G39: 64200.98 | H39: 40066 | I39: 40074 | J39: 0 | K39: 0 | L39: 3000 | M39: Heavy Rain | N39: 2 | O39: =YEAR(H39) -> 2009
A40: 3555 | B40: 0 | C40: Nigeria | D40: 0 | E40: 6.5097 | F40: 5.54356 | G40: 53018.49 | H40: 40106 | I40: 40112 | J40: 0 | K40: 0 | L40: 5000 | M40: Heavy Rain | N40: 1 | O40: =YEAR(H40) -> 2009
A41: 3715 | B41: 0 | C41: Nigeria | D41: 0 | E41: 4.5 | F41: 12.78 | G41: 8694.6 | H41: 40434 | I41: 40451 | J41: News | K41: 40 | L41: 10000 | M41: Heavy Rain and Dam Break | N41: 1.5 | O41: =YEAR(H41) -> 2010
A42: 3839 | C42: Nigeria | E42: 8.6417 | F42: 12.5947 | G42: 103000.35 | H42: 40739 | I42: 40746 | J42: News | K42: 13 | L42: 1000 | M42: Heavy Rain | N42: 1.5 | O42: =YEAR(H42) -> 2011
A43: 3860 | C43: Nigeria | E43: 4.47296 | F43: 8.73715 | G43: 20013.55 | H43: 40781 | I43: 40794 | J43: News | K43: 20 | L43: 3000 | M43: Torrential Rain | N43: 1.5 | O43: =YEAR(H43) -> 2011
A44: 3901 | C44: Nigeria | D44: Camaroun | E44: 12.8074 | F44: 9.85967 | G44: 50438.09 | H44: 40959 | I44: 40966 | J44: News | K44: 5 | L44: 300 | M44: Heavy Rain | N44: 1 | O44: =YEAR(H44) -> 2012
A45: 3954 | C45: Nigeria | E45: 8.0195 | F45: 10.5918 | G45: 45292.27 | H45: 41112 | I45: 41115 | J45: News | K45: 50 | L45: 2000 | M45: Heavy Rain | N45: 1.5 | O45: =YEAR(H45) -> 2012
A46: 3964 | C46: Nigeria | E46: 11.2812 | F46: 7.42738 | G46: 16652.25 | H46: 41123 | I46: 41127 | J46: News | K46: 0 | L46: 3000 | M46: Torrential Rain | N46: 1.5 | O46: =YEAR(H46) -> 2012
A47: 3972 | C47: Nigeria | E47: 4.12488 | F47: 14.316 | G47: 48922.93 | H47: 41145 | I47: 41150 | J47: News | K47: 10 | L47: 20000 | M47: Torrential Rain | N47: 1.5 | O47: =YEAR(H47) -> 2012
A48: 3976 | C48: Nigeria | D48: Camaroun | E48: 12.1089 | F48: 9.30166 | G48: 96830.55 | H48: 41146 | I48: 41178 | J48: News | K48: 127 | L48: 20000 | M48: Heavy Rain | N48: 1.5 | O48: =YEAR(H48) -> 2012
...

Sheet Annual Flood
A1: Flood Annual | B1: Year | C1: Total Flood Area (km2)
A2: 1985 | B2: =COUNTIF(Flood_Data!$O$2:$O$1000,A2) -> 1 | C2: =SUMIF(Flood_Data!$O$2:$O$69,A2,Flood_Data!$G$2:$G$69) -> 74615.9 | E2: =A2=1985 -> TRUE
A3: =A2+1 -> 1986 | B3: =COUNTIF(Flood_Data!$O$2:$O$1000,A3) -> 0 | C3: =SUMIF(Flood_Data!$O$2:$O$69,A3,Flood_Data!$G$2:$G$69) -> 0 | E3: =COUNTIF(Flood_Data!O:O,1985) -> 1
A4: =A3+1 -> 1987 | B4: =COUNTIF(Flood_Data!$O$2:$O$1000,A4) -> 0 | C4: =SUMIF(Flood_Data!$O$2:$O$69,A4,Flood_Data!$G$2:$G$69) -> 0 | E4: =SUM(Flood_Data!G2) -> 74615.9
A5: =A4+1 -> 1988 | B5: =COUNTIF(Flood_Data!$O$2:$O$1000,A5) -> 6 | C5: =SUMIF(Flood_Data!$O$2:$O$69,A5,Flood_Data!$G$2:$G$69) -> 147463.99
A6: =A5+1 -> 1989 | B6: =COUNTIF(Flood_Data!$O$2:$O$1000,A6) -> 0 | C6: =SUMIF(Flood_Data!$O$2:$O$69,A6,Flood_Data!$G$2:$G$69) -> 0
A7: =A6+1 -> 1990 | B7: =COUNTIF(Flood_Data!$O$2:$O$1000,A7) -> 3 | C7: =SUMIF(Flood_Data!$O$2:$O$69,A7,Flood_Data!$G$2:$G$69) -> 45061.73
A8: =A7+1 -> 1991 | B8: =COUNTIF(Flood_Data!$O$2:$O$1000,A8) -> 1 | C8: =SUMIF(Flood_Data!$O$2:$O$69,A8,Flood_Data!$G$2:$G$69) -> 22908.02
A9: =A8+1 -> 1992 | B9: =COUNTIF(Flood_Data!$O$2:$O$1000,A9) -> 1 | C9: =SUMIF(Flood_Data!$O$2:$O$69,A9,Flood_Data!$G$2:$G$69) -> 42369.21
A10: =A9+1 -> 1993 | B10: =COUNTIF(Flood_Data!$O$2:$O$1000,A10) -> 0 | C10: =SUMIF(Flood_Data!$O$2:$O$69,A10,Flood_Data!$G$2:$G$69) -> 0
A11: =A10+1 -> 1994 | B11: =COUNTIF(Flood_Data!$O$2:$O$1000,A11) -> 1 | C11: =SUMIF(Flood_Data!$O$2:$O$69,A11,Flood_Data!$G$2:$G$69) -> 317262.41
A12: =A11+1 -> 1995 | B12: =COUNTIF(Flood_Data!$O$2:$O$1000,A12) -> 1 | C12: =SUMIF(Flood_Data!$O$2:$O$69,A12,Flood_Data!$G$2:$G$69) -> 19768.44
A13: =A12+1 -> 1996 | B13: =COUNTIF(Flood_Data!$O$2:$O$1000,A13) -> 0 | C13: =SUMIF(Flood_Data!$O$2:$O$69,A13,Flood_Data!$G$2:$G$69) -> 0
A14: =A13+1 -> 1997 | B14: =COUNTIF(Flood_Data!$O$2:$O$1000,A14) -> 1 | C14: =SUMIF(Flood_Data!$O$2:$O$69,A14,Flood_Data!$G$2:$G$69) -> 17287.47
A15: =A14+1 -> 1998 | B15: =COUNTIF(Flood_Data!$O$2:$O$1000,A15) -> 2 | C15: =SUMIF(Flood_Data!$O$2:$O$69,A15,Flood_Data!$G$2:$G$69) -> 68804.11
A16: =A15+1 -> 1999 | B16: =COUNTIF(Flood_Data!$O$2:$O$1000,A16) -> 2 | C16: =SUMIF(Flood_Data!$O$2:$O$69,A16,Flood_Data!$G$2:$G$69) -> 1113252
... A39: =A38+1 -> 2022 | B39: =COUNTIF(Flood_Data!$O$2:$O$1000,A39) -> 0 | C39: =SUMIF(Flood_Data!$O$2:$O$69,A39,Flood_Data!$G$2:$G$69) -> 0

Sheet Flood Annual Final
A1: Year | B1: Flood Events | C1: Total Flooded Area (km2) | D1: Annual Rainfall (mm) | H1: Rainfall X | I1: Flooded Area Y
A2: 1985 | B2: =COUNTIF(Flood_Data!$O$2:$O$69,A2) -> 1 | C2: =SUMIF(Flood_Data!$O$2:$O$69,A2,Flood_Data!$G$2:$G$69) -> 74615.9 | D2: {=INDEX([1]Annual_Rainfall!$B$2:$B$126,MATCH(A2,[1]Annual_Rainfall!$A$2:$A$126,0))} -> 1119.45 | F2: =COUNTBLANK(D2:D39) -> 0 | H2: =D2 -> 1119.45 | I2: =C2 -> 74615.9
A3: 1986 | B3: =COUNTIF(Flood_Data!$O$2:$O$69,A3) -> 0 | C3: =SUMIF(Flood_Data!$O$2:$O$69,A3,Flood_Data!$G$2:$G$69) -> 0 | D3: {=INDEX([1]Annual_Rainfall!$B$2:$B$126,MATCH(A3,[1]Annual_Rainfall!$A$2:$A$126,0))} -> 1073.18 | F3: {=CORREL(B2:B39,D2:D39)} -> 0.34093818 | H3: =D3 -> 1073.18 | I3: =C3 -> 0
A4: 1987 | B4: =COUNTIF(Flood_Data!$O$2:$O$69,A4) -> 0 | C4: =SUMIF(Flood_Data!$O$2:$O$69,A4,Flood_Data!$G$2:$G$69) -> 0 | D4: {=INDEX([1]Annual_Rainfall!$B$2:$B$126,MATCH(A4,[1]Annual_Rainfall!$A$2:$A$126,0))} -> 1025.86 | F4: {=CORREL(B2:B39,D2:D39)^2} -> 0.11623884 | H4: =D4 -> 1025.86 | I4: =C4 -> 0
A5: 1988 | B5: =COUNTIF(Flood_Data!$O$2:$O$69,A5) -> 6 | C5: =SUMIF(Flood_Data!$O$2:$O$69,A5,Flood_Data!$G$2:$G$69) -> 147463.99 | D5: {=INDEX([1]Annual_Rainfall!$B$2:$B$126,MATCH(A5,[1]Annual_Rainfall!$A$2:$A$126,0))} -> 1195.07 | F5: {=CORREL(C2:C39,D2:D39)} -> 0.43905807 | H5: =D5 -> 1195.07 | I5: =C5 -> 147463.99
A6: 1989 | B6: =COUNTIF(Flood_Data!$O$2:$O$69,A6) -> 0 | C6: =SUMIF(Flood_Data!$O$2:$O$69,A6,Flood_Data!$G$2:$G$69) -> 0 | D6: {=INDEX([1]Annual_Rainfall!$B$2:$B$126,MATCH(A6,[1]Annual_Rainfall!$A$2:$A$126,0))} -> 1148.31 | F6: {=CORREL(C2:C39,D2:D39)^2} -> 0.19277199 | H6: =D6 -> 1148.31 | I6: =C6 -> 0
A7: 1990 | B7: =COUNTIF(Flood_Data!$O$2:$O$69,A7) -> 3 | C7: =SUMIF(Flood_Data!$O$2:$O$69,A7,Flood_Data!$G$2:$G$69) -> 45061.73 | D7: {=INDEX([1]Annual_Rainfall!$B$2:$B$126,MATCH(A7,[1]Annual_Rainfall!$A$2:$A$126,0))} -> 1097.4 | F7: {=CORREL(H2:H39,I2:I39)} -> 0.43905807 | H7: =D7 -> 1097.4 | I7: =C7 -> 45061.73
A8: 1991 | B8: =COUNTIF(Flood_Data!$O$2:$O$69,A8) -> 1 | C8: =SUMIF(Flood_Data!$O$2:$O$69,A8,Flood_Data!$G$2:$G$69) -> 22908.02 | D8: {=INDEX([1]Annual_Rainfall!$B$2:$B$126,MATCH(A8,[1]Annual_Rainfall!$A$2:$A$126,0))} -> 1254.64 | F8: {=RSQ(I2:I39,H2:H39)} -> 0.19277199 | H8: =D8 -> 1254.64 | I8: =C8 -> 22908.02
A9: 1992 | B9: =COUNTIF(Flood_Data!$O$2:$O$69,A9) -> 1 | C9: =SUMIF(Flood_Data!$O$2:$O$69,A9,Flood_Data!$G$2:$G$69) -> 42369.21 | D9: {=INDEX([1]Annual_Rainfall!$B$2:$B$126,MATCH(A9,[1]Annual_Rainfall!$A$2:$A$126,0))} -> 1119.42 | F9: =MAX(C2:C39) -> 1471789.5 | H9: =D9 -> 1119.42 | I9: =C9 -> 42369.21
A10: 1993 | B10: =COUNTIF(Flood_Data!$O$2:$O$69,A10) -> 0 | C10: =SUMIF(Flood_Data!$O$2:$O$69,A10,Flood_Data!$G$2:$G$69) -> 0 | D10: {=INDEX([1]Annual_Rainfall!$B$2:$B$126,MATCH(A10,[1]Annual_Rainfall!$A$2:$A$126,0))} -> 1084.92 | F10: {=INDEX(A2:A39,MATCH(MAX(C2:C39),C2:C39,0))} -> 2019 | H10: =D10 -> 1084.92 | I10: =C10 -> 0
A11: 1994 | B11: =COUNTIF(Flood_Data!$O$2:$O$69,A11) -> 1 | C11: =SUMIF(Flood_Data!$O$2:$O$69,A11,Flood_Data!$G$2:$G$69) -> 317262.41 | D11: {=INDEX([1]Annual_Rainfall!$B$2:$B$126,MATCH(A11,[1]Annual_Rainfall!$A$2:$A$126,0))} -> 1236.95 | F11: {=INDEX(D2:D39,MATCH(2019,A2:A39,0))} -> 1296.65 | H11: =D11 -> 1236.95 | I11: =C11 -> 317262.41
A12: 1995 | B12: =COUNTIF(Flood_Data!$O$2:$O$69,A12) -> 1 | C12: =SUMIF(Flood_Data!$O$2:$O$69,A12,Flood_Data!$G$2:$G$69) -> 19768.44 | D12: {=INDEX([1]Annual_Rainfall!$B$2:$B$126,MATCH(A12,[1]Annual_Rainfall!$A$2:$A$126,0))} -> 1200.49 | F12: {=INDEX(B2:B39,MATCH(2019,A2:A39,0))} -> 4 | H12: =D12 -> 1200.49 | I12: =C12 -> 19768.44
A13: 1996 | B13: =COUNTIF(Flood_Data!$O$2:$O$69,A13) -> 0 | C13: =SUMIF(Flood_Data!$O$2:$O$69,A13,Flood_Data!$G$2:$G$69) -> 0 | D13: {=INDEX([1]Annual_Rainfall!$B$2:$B$126,MATCH(A13,[1]Annual_Rainfall!$A$2:$A$126,0))} -> 1245.22 | F13: =AVERAGE(B2:B39) -> 1.7894737 | H13: =D13 -> 1245.22 | I13: =C13 -> 0
A14: 1997 | B14: =COUNTIF(Flood_Data!$O$2:$O$69,A14) -> 1 | C14: =SUMIF(Flood_Data!$O$2:$O$69,A14,Flood_Data!$G$2:$G$69) -> 17287.47 | D14: {=INDEX([1]Annual_Rainfall!$B$2:$B$126,MATCH(A14,[1]Annual_Rainfall!$A$2:$A$126,0))} -> 1231.11 | F14: =MAX(B2:B39) -> 9 | H14: =D14 -> 1231.11 | I14: =C14 -> 17287.47
A15: 1998 | B15: =COUNTIF(Flood_Data!$O$2:$O$69,A15) -> 2 | C15: =SUMIF(Flood_Data!$O$2:$O$69,A15,Flood_Data!$G$2:$G$69) -> 68804.11 | D15: {=INDEX([1]Annual_Rainfall!$B$2:$B$126,MATCH(A15,[1]Annual_Rainfall!$A$2:$A$126,0))} -> 1167.51 | F15: {=insex} -> #NAME? | H15: =D15 -> 1167.51 | I15: =C15 -> 68804.11
A16: 1999 | B16: =COUNTIF(Flood_Data!$O$2:$O$69,A16) -> 2 | C16: =SUMIF(Flood_Data!$O$2:$O$69,A16,Flood_Data!$G$2:$G$69) -> 1113252 | D16: {=INDEX([1]Annual_Rainfall!$B$2:$B$126,MATCH(A16,[1]Annual_Rainfall!$A$2:$A$126,0))} -> 1242.61 | F16: {=INDEX(A2:A39,MATCH(MAX(B2:B39),B2:B39,0))} -> 2003 | H16: =D16 -> 1242.61 | I16: =C16 -> 1113252
A17: 2000 | B17: =COUNTIF(Flood_Data!$O$2:$O$69,A17) -> 1 | C17: =SUMIF(Flood_Data!$O$2:$O$69,A17,Flood_Data!$G$2:$G$69) -> 7724.63 | D17: {=INDEX([1]Annual_Rainfall!$B$2:$B$126,MATCH(A17,[1]Annual_Rainfall!$A$2:$A$126,0))} -> 1139.23 | F17: {=INDEX(D2:D39,MATCH(2003,A2:A39,0))} -> 1277.68 | H17: =D17 -> 1139.23 | I17: =C17 -> 7724.63
A18: 2001 | B18: =COUNTIF(Flood_Data!$O$2:$O$69,A18) -> 2 | C18: =SUMIF(Flood_Data!$O$2:$O$69,A18,Flood_Data!$G$2:$G$69) -> 15352.34 | D18: {=INDEX([1]Annual_Rainfall!$B$2:$B$126,MATCH(A18,[1]Annual_Rainfall!$A$2:$A$126,0))} -> 1152.11 | F18: =MIN(B2:B39) -> 0 | H18: =D18 -> 1152.11 | I18: =C18 -> 15352.34
A19: 2002 | B19: =COUNTIF(Flood_Data!$O$2:$O$69,A19) -> 1 | C19: =SUMIF(Flood_Data!$O$2:$O$69,A19,Flood_Data!$G$2:$G$69) -> 1657.33 | D19: {=INDEX([1]Annual_Rainfall!$B$2:$B$126,MATCH(A19,[1]Annual_Rainfall!$A$2:$A$126,0))} -> 1166.44 | F19: {=INDEX(A2:A39,MATCH(MIN(B2:B39),B2:B39,0))} -> 1986 | H19: =D19 -> 1166.44 | I19: =C19 -> 1657.33
A20: 2003 | B20: =COUNTIF(Flood_Data!$O$2:$O$69,A20) -> 9 | C20: =SUMIF(Flood_Data!$O$2:$O$69,A20,Flood_Data!$G$2:$G$69) -> 449965.88 | D20: {=INDEX([1]Annual_Rainfall!$B$2:$B$126,MATCH(A20,[1]Annual_Rainfall!$A$2:$A$126,0))} -> 1277.68 | F20: =COUNTIF(B2:B39,0) -> 9 | H20: =D20 -> 1277.68 | I20: =C20 -> 449965.88
A21: 2004 | B21: =COUNTIF(Flood_Data!$O$2:$O$69,A21) -> 5 | C21: =SUMIF(Flood_Data!$O$2:$O$69,A21,Flood_Data!$G$2:$G$69) -> 35839.844 | D21: {=INDEX([1]Annual_Rainfall!$B$2:$B$126,MATCH(A21,[1]Annual_Rainfall!$A$2:$A$126,0))} -> 1148.15 | F21: {=_xlfn._xlws.FILTER(A2:A39,B2:B39=0)} -> 1986 | H21: =D21 -> 1148.15 | I21: =C21 -> 35839.844
A22: 2005 | B22: =COUNTIF(Flood_Data!$O$2:$O$69,A22) -> 2 | C22: =SUMIF(Flood_Data!$O$2:$O$69,A22,Flood_Data!$G$2:$G$69) -> 171050.48 | D22: {=INDEX([1]Annual_Rainfall!$B$2:$B$126,MATCH(A22,[1]Annual_Rainfall!$A$2:$A$126,0))} -> 1187.66 | F22: 1987 | H22: =D22 -> 1187.66 | I22: =C22 -> 171050.48
A23: 2006 | B23: =COUNTIF(Flood_Data!$O$2:$O$69,A23) -> 3 | C23: =SUMIF(Flood_Data!$O$2:$O$69,A23,Flood_Data!$G$2:$G$69) -> 3445.332 | D23: {=INDEX([1]Annual_Rainfall!$B$2:$B$126,MATCH(A23,[1]Annual_Rainfall!$A$2:$A$126,0))} -> 1182.62 | F23: 1989 | H23: =D23 -> 1182.62 | I23: =C23 -> 3445.332
A24: 2007 | B24: =COUNTIF(Flood_Data!$O$2:$O$69,A24) -> 2 | C24: =SUMIF(Flood_Data!$O$2:$O$69,A24,Flood_Data!$G$2:$G$69) -> 635389.03 | D24: {=INDEX([1]Annual_Rainfall!$B$2:$B$126,MATCH(A24,[1]Annual_Rainfall!$A$2:$A$126,0))} -> 1186.85 | F24: 1993 | H24: =D24 -> 1186.85 | I24: =C24 -> 635389.03
A25: 2008 | B25: =COUNTIF(Flood_Data!$O$2:$O$69,A25) -> 0 | C25: =SUMIF(Flood_Data!$O$2:$O$69,A25,Flood_Data!$G$2:$G$69) -> 0 | D25: {=INDEX([1]Annual_Rainfall!$B$2:$B$126,MATCH(A25,[1]Annual_Rainfall!$A$2:$A$126,0))} -> 1205.15 | F25: 1996 | H25: =D25 -> 1205.15 | I25: =C25 -> 0
A26: 2009 | B26: =COUNTIF(Flood_Data!$O$2:$O$69,A26) -> 2 | C26: =SUMIF(Flood_Data!$O$2:$O$69,A26,Flood_Data!$G$2:$G$69) -> 117219.47 | D26: {=INDEX([1]Annual_Rainfall!$B$2:$B$126,MATCH(A26,[1]Annual_Rainfall!$A$2:$A$126,0))} -> 1152.55 | F26: 2008 | H26: =D26 -> 1152.55 | I26: =C26 -> 117219.47
A27: 2010 | B27: =COUNTIF(Flood_Data!$O$2:$O$69,A27) -> 1 | C27: =SUMIF(Flood_Data!$O$2:$O$69,A27,Flood_Data!$G$2:$G$69) -> 8694.6 | D27: {=INDEX([1]Annual_Rainfall!$B$2:$B$126,MATCH(A27,[1]Annual_Rainfall!$A$2:$A$126,0))} -> 1236.44 | F27: 2014 | H27: =D27 -> 1236.44 | I27: =C27 -> 8694.6
A28: 2011 | B28: =COUNTIF(Flood_Data!$O$2:$O$69,A28) -> 2 | C28: =SUMIF(Flood_Data!$O$2:$O$69,A28,Flood_Data!$G$2:$G$69) -> 123013.9 | D28: {=INDEX([1]Annual_Rainfall!$B$2:$B$126,MATCH(A28,[1]Annual_Rainfall!$A$2:$A$126,0))} -> 1050.75 | F28: 2016 | H28: =D28 -> 1050.75 | I28: =C28 -> 123013.9
A29: 2012 | B29: =COUNTIF(Flood_Data!$O$2:$O$69,A29) -> 6 | C29: =SUMIF(Flood_Data!$O$2:$O$69,A29,Flood_Data!$G$2:$G$69) -> 270674.49 | D29: {=INDEX([1]Annual_Rainfall!$B$2:$B$126,MATCH(A29,[1]Annual_Rainfall!$A$2:$A$126,0))} -> 1240.11 | F29: 2022 | H29: =D29 -> 1240.11 | I29: =C29 -> 270674.49
A30: 2013 | B30: =COUNTIF(Flood_Data!$O$2:$O$69,A30) -> 1 | C30: =SUMIF(Flood_Data!$O$2:$O$69,A30,Flood_Data!$G$2:$G$69) -> 178191.77 | D30: {=INDEX([1]Annual_Rainfall!$B$2:$B$126,MATCH(A30,[1]Annual_Rainfall!$A$2:$A$126,0))} -> 1069.17 | F30: =AVERAGE(C2:C39) -> 172136.45 | H30: =D30 -> 1069.17 | I30: =C30 -> 178191.77
A31: 2014 | B31: =COUNTIF(Flood_Data!$O$2:$O$69,A31) -> 0 | C31: =SUMIF(Flood_Data!$O$2:$O$69,A31,Flood_Data!$G$2:$G$69) -> 0 | D31: {=INDEX([1]Annual_Rainfall!$B$2:$B$126,MATCH(A31,[1]Annual_Rainfall!$A$2:$A$126,0))} -> 1144.34 | F31: =AVERAGE(C2:C39) -> 172136.45 | H31: =D31 -> 1144.34 | I31: =C31 -> 0
A32: 2015 | B32: =COUNTIF(Flood_Data!$O$2:$O$69,A32) -> 1 | C32: =SUMIF(Flood_Data!$O$2:$O$69,A32,Flood_Data!$G$2:$G$69) -> 186816.02 | D32: {=INDEX([1]Annual_Rainfall!$B$2:$B$126,MATCH(A32,[1]Annual_Rainfall!$A$2:$A$126,0))} -> 1032.6 | F32: =MAX(C2:C39) -> 1471789.5 | H32: =D32 -> 1032.6 | I32: =C32 -> 186816.02
A33: 2016 | B33: =COUNTIF(Flood_Data!$O$2:$O$69,A33) -> 0 | C33: =SUMIF(Flood_Data!$O$2:$O$69,A33,Flood_Data!$G$2:$G$69) -> 0 | D33: {=INDEX([1]Annual_Rainfall!$B$2:$B$126,MATCH(A33,[1]Annual_Rainfall!$A$2:$A$126,0))} -> 1202.33 | F33: =MIN(C2:CC39) -> #NAME? | H33: =D33 -> 1202.33 | I33: =C33 -> 0
A34: 2017 | B34: =COUNTIF(Flood_Data!$O$2:$O$69,A34) -> 2 | C34: =SUMIF(Flood_Data!$O$2:$O$69,A34,Flood_Data!$G$2:$G$69) -> 111091.46 | D34: {=INDEX([1]Annual_Rainfall!$B$2:$B$126,MATCH(A34,[1]Annual_Rainfall!$A$2:$A$126,0))} -> 1156.19 | F34: =MIN(C2:C39) -> 0 | H34: =D34 -> 1156.19 | I34: =C34 -> 111091.46
A35: 2018 | B35: =COUNTIF(Flood_Data!$O$2:$O$69,A35) -> 2 | C35: =SUMIF(Flood_Data!$O$2:$O$69,A35,Flood_Data!$G$2:$G$69) -> 320377.82 | D35: {=INDEX([1]Annual_Rainfall!$B$2:$B$126,MATCH(A35,[1]Annual_Rainfall!$A$2:$A$126,0))} -> 1259.86 | F35: =COUNTIF(C2:C39,0) -> 9 | H35: =D35 -> 1259.86 | I35: =C35 -> 320377.82
A36: 2019 | B36: =COUNTIF(Flood_Data!$O$2:$O$69,A36) -> 4 | C36: =SUMIF(Flood_Data!$O$2:$O$69,A36,Flood_Data!$G$2:$G$69) -> 1471789.5 | D36: {=INDEX([1]Annual_Rainfall!$B$2:$B$126,MATCH(A36,[1]Annual_Rainfall!$A$2:$A$126,0))} -> 1296.65 | F36: =MAX(D2:D39) -> 1296.65 | H36: =D36 -> 1296.65 | I36: =C36 -> 1471789.5
A37: 2020 | B37: =COUNTIF(Flood_Data!$O$2:$O$69,A37) -> 2 | C37: =SUMIF(Flood_Data!$O$2:$O$69,A37,Flood_Data!$G$2:$G$69) -> 449138.64 | D37: {=INDEX([1]Annual_Rainfall!$B$2:$B$126,MATCH(A37,[1]Annual_Rainfall!$A$2:$A$126,0))} -> 1255.3 | F37: =MIN(D2:D39) -> 1025.86 | H37: =D37 -> 1255.3 | I37: =C37 -> 449138.64
A38: 2021 | B38: =COUNTIF(Flood_Data!$O$2:$O$69,A38) -> 1 | C38: =SUMIF(Flood_Data!$O$2:$O$69,A38,Flood_Data!$G$2:$G$69) -> 114959.47 | D38: {=INDEX([1]Annual_Rainfall!$B$2:$B$126,MATCH(A38,[1]Annual_Rainfall!$A$2:$A$126,0))} -> 1118.94 | F38: {=INDEX(A2:A39,MATCH(MIN(D2:D39),D2:D39,0))} -> 1987 | H38: =D38 -> 1118.94 | I38: =C38 -> 114959.47
A39: 2022 | B39: =COUNTIF(Flood_Data!$O$2:$O$69,A39) -> 0 | C39: =SUMIF(Flood_Data!$O$2:$O$69,A39,Flood_Data!$G$2:$G$69) -> 0 | D39: {=INDEX([1]Annual_Rainfall!$B$2:$B$126,MATCH(A39,[1]Annual_Rainfall!$A$2:$A$126,0))} -> 1226.07 | F39: =MAX(D2:D39) -> 1296.65 | H39: =D39 -> 1226.07 | I39: =C39 -> 0
F40: {=INDEX(A2:A39,MATCH(MAX(D2:D39),D2:D39,0))} -> 2019
...
